Workbook

Sheet Class-E Calculator
B2: CLASS-E RF POWER AMPLIFIER · DESIGN CALCULATOR
B3: Based on Sokal/Raab equations (WA1HQC · QEX Jan/Feb 2001) | Optimum (ZVS + ZCS) Class-E switching
B4: By Emiliano Gonzalez LU3VEA – lu3vea@gmail.com – License: GPL v3
B6: ⚙ ITERATIVE CALCULATION REQUIRED — File → Options → Formulas → Enable Iterative Calculation (100 iterations, max change 0.0001). LibreOffice: Tools → Options → LibreOffice Calc → Calculate → Iterations. Press F9 until η (C88) stabilises. Circular chain: η(C88) → I_dc(C43) → RFC loss term [−ESR_RFC·I_dc/(Vcc−ΔV)] & Coss-fraction term [−J95/((Vcc−ΔV)·I_dc)] in J96 → η(C88). NOTE: J95 = Coss power [W] (NOT RFC loss) — the RFC loss and Coss loss fraction are both in J96.. [R(C42), C1(C48), C2(C52), L2(C50), and RFC(C54) are NOT part of the circular chain — they depend only on fixed inputs and are valid from the first calculation.] | C6: =IF(NOT(ISNUMBER(C88)),"🚨 CRITICAL: Enable iterative calculation (File→Options→Formulas, 100 iter, 0.0001 tol) then press F9",IF(C42>0,"⚡ Press F9 until η (D6) stops changing. Current η="&TEXT(IF(ISNUMBER(C88),C88,C21),"0.0000")&" — if this value changes when you press F9, keep pressing. When stable: ✅ CONVERGED.","⚠ R invalid — check QL input")) -> ⚡ Press F9 until η (D6) stops changing. Current η=00.001 — if this value changes when you press F9, keep pressing. When stable: ✅ CONVERGED. | D6: =C88 -> 0.75338157
B8: MOSFET MODEL
B9: BS170 | I9: =IF(ISNUMBER(IFERROR(VLOOKUP(B9,'MOSFET Reference Table'!$A:$E,5,0)*1,0)),"","⚠ LDMOS/no Rds(on) — efficiency model INACTIVE for this device. C88 returns a warning string; I_dc uses input η (C21); no loss calculation is performed. Verify η from manufacturer datasheet or LTspice simulation.")
B10: Min. MOSFET V_DSS Required (V)
B11: =C84 -> 53.43
B12: =IF(IFERROR(VLOOKUP(B9,'MOSFET Reference Table'!$A:$C,3,0)*1,0)<C84,"🚨 V_DSS TOO LOW — MOSFET WILL FAIL! V_DSS="&TEXT(IFERROR(VLOOKUP(B9,'MOSFET Reference Table'!$A:$C,3,0),"?"),"0")&"V < required "&TEXT(C84,"0")&"V",IF(IFERROR(VLOOKUP(B9,'MOSFET Reference Table'!$A:$D,4,0)*1,999)>=C86,"✅ V_DSS OK | I_D(cont) OK vs I_pk (⚠ verify I_D(pulsed) ≥ I_pk if I_D(cont) is marginal)",IF(IFERROR(VLOOKUP(B9,'MOSFET Reference Table'!$A:$D,4,0)*1,999)>=C86/2,"⚠ V_DSS OK | I_D(cont)="&TEXT(IFERROR(VLOOKUP(B9,'MOSFET Reference Table'!$A:$D,4,0),"?"),"0.0")&"A < I_pk="&TEXT(C86,"0.00")&"A — I_D(cont) < I_pk but pulsed rating is typically 2-4× higher. Verify I_D(pulsed) from datasheet ≥ I_pk.","✅ V_DSS OK | ⚠ I_D(cont)="&TEXT(IFERROR(VLOOKUP(B9,'MOSFET Reference Table'!$A:$D,4,0),"?"),"0.0")&"A < I_pk="&TEXT(C86,"0.00")&"A — check I_D(pulsed) in datasheet"))) -> ✅ V_DSS OK | I_D(cont) OK vs I_pk (⚠ verify I_D(pulsed) ≥ I_pk if I_D(cont) is marginal)
B14: INPUT PARAMETERS
B15: Parameter | C15: Value | D15: Unit
B16: Supply Voltage (Vcc) | C16: 5 | D16: V
B17: Output Power (P_out) | C17: 0.4 | D17: W
B18: Operating Frequency (f) | C18: 14 | D18: MHz | E18: =IF(C18>1000,"🚨 Frequency appears to be in Hz, not MHz. Enter MHz only (e.g., 14 for 14 MHz).",IF(C18<0.001,"🚨 Frequency appears too low. Enter value in MHz.","✅ f = "&TEXT(C18,"0.000")&" MHz")) -> ✅ f = 0.014 MHz
B19: Loaded Q Factor (Q_L) | C19: 5 | D19: — | E19: =IF(NOT(ISNUMBER(C19)),"QL must be a number (e.g., 5)",IF(C19<=0,"QL must be positive (min 1.7879)",IF(C19<1.7879,"QL<1.7879 minimum — Class-E impossible",IF(C18>30,"QL valid. For f>30 MHz, try QL=3–5 to keep L2 manageable.",IF(C18>14,"QL valid. For 14–30 MHz HF, QL=5–7 recommended.",IF(C18>3,"QL valid. For 3–14 MHz HF, QL=5–10 gives good balance.","QL valid. For LF/MF (<3 MHz), QL=7–15 allows excellent efficiency.")))))) -> QL valid. For 3–14 MHz HF, QL=5–10 gives good balance.
B20: Transistor V_sat (Vo) [0 for MOSFET, 0.1–1 V for BJT] | C20: 0 | D20: V
B21: Drain Efficiency (η) | C21: 0.92 | D21: — | E21: =IF(OR(C21<=0,C21>=1),"🚨 FATAL: η must be between 0.01 and 0.99 (e.g., 0.85)",IF(ISNUMBER(C88),IF(ABS(C88-C21)>0.02,"ℹ C21="&TEXT(C21,"0%")&" differs from analytical C88="&TEXT(C88,"0.0%")&". C88 (predicted η) is always used for I_dc — C21 is informational only.","✅ η (C88) converged. C21 is informational only."),"⚠ C88 not numeric — check MOSFET table or enter η in C21")) -> ℹ C21=92% differs from analytical C88=75%. C88 (predicted η) is always used for I_dc — C21 is informational only.
B22: ESR_L2 (L2 winding series resistance) | C22: 0.05 | D22: Ω | F22: ℹ ESR_L2: series resonant inductor (L2) winding resistance. Typical: 0.03–0.08 Ω small air-core solenoid; 0.05–0.15 Ω wound toroid at HF. Enters Sokal Eq. 1 with full weight (coefficient 1.0) — errors here corrupt η, R, C1, C2, and I_dc directly. Measure with LCR meter or VNA at operating frequency. Do NOT enter RFC ESR here — that belongs in C23.
B23: RFC Winding ESR (ESR_RFC) | C23: 0.1 | D23: Ω | F23: ℹ RFC choke winding ESR. Typical: 0.05–0.1 Ω air-core toroid; 0.1–0.5 Ω wound ferrite at HF; up to 1 Ω for small ferrite pot cores. Used in η model. Loss ≈ ESR_RFC × I_dc². Measure with LCR meter or VNA at operating frequency. | G23: =IF(AND(ISNUMBER(C23),ISNUMBER(C43),MAX(C16-C35,0.001)>0),IF(ABS(C23*C43/(MAX(C16-C35,0.001))-0.01)>0.005,"⚠ RFC actual loss="&TEXT(C23*C43/(MAX(C16-C35,0.001))*100,"0.0")&"% vs Sokal fixed 1% (−0.01 term). Δη="&TEXT(C23*C43/(MAX(C16-C35,0.001))-0.01,"0.000")&". Adjust input η (C20) accordingly.","✅ RFC loss≈"&TEXT(C23*C43/(MAX(C16-C35,0.001))*100,"0.0")&"% — Sokal −0.01 fixed term accurate."),"—") -> ⚠ RFC actual loss=00% vs Sokal fixed 1% (−0.01 term). Δη=0.000. Adjust input η (C20) accordingly.
B24: Source Impedance (Z_in) | C24: 50 | D24: Ω
B25: Load Impedance Z_out (antenna/load) | C25: 50 | D25: Ω
B26: Duty Cycle (D) | C26: 0.5 | D26: — | E26: =IF(C26<>0.5,"🚨 FATAL: D≠0.5 — ALL SOKAL EQUATIONS INVALID. Reset to 0.5.","✅ D = 0.5 — correct (required for Sokal equations)") -> ✅ D = 0.5 — correct (required for Sokal equations)
B27: MOSFET Ciss (from datasheet) | C27: =IFERROR(IF(B9="-- Select MOSFET --",100,VLOOKUP(B9,'MOSFET Reference Table'!$A:$F,6,0)),100) -> 60 | D27: pF
B28: Gate Damping Resistor (R_gate) | C28: 10 | D28: Ω
B29: Ambient Temperature (T_amb) | C29: 25 | D29: °C
B30: ESR_C2 (C2 capacitor series resistance) | C30: 0.01 | D30: Ω
B31: ESR_C1 (C1 shunt capacitor series resistance) | C31: 0.01 | D31: Ω
B32: C_oss | C32: =IFERROR(VLOOKUP(B9,'MOSFET Reference Table'!$A:$G,7,0),0) -> 12 | D32: pF | H32: =IF(AND(B9<>"-- Select MOSFET --",IFERROR(VLOOKUP(B9,'MOSFET Reference Table'!$A:$A,1,0),"not found")="not found"),"⚠ MOSFET not in reference table — Coss returned as 0 pF. C1_ext (C33) will be over-estimated. Add device to the MOSFET Reference Table.","")
B33: C1_ext (= C1_total − Coss_effective; Coss_effective = C32 × C36, where C32 = Coss datasheet [pF], C36 = bias-point scale factor) ⚠ C32 is approximate. For best accuracy, use a VNA to measure Coss at Vds ≈ 0.5×Vcc, or use manufacturer's energy-equivalent Coss (Coss,er) if provided. | C33: =IFERROR(IF(NOT(ISNUMBER(C49)),IF(NOT(ISNUMBER(C48)),C48,"⚠ C1_ext invalid — check QL input (C19) and frequency (C18)"),IF(C49-C32*$C$36<0,"🚨 OVER-CAPACITANCE: Coss_eff ("&TEXT(C32*$C$36,"0.0")&" pF) > C1_req ("&TEXT(C49,"0.0")&" pF). Select a device with lower Coss, reduce f, or increase Pout/Vcc.",MAX(C49-C32*$C$36,0))),0) -> 73.131181 | D33: pF
B34: MOSFET fall time t_f [ns] — overrides fT model when > 0 | C34: 0 | D34: ns
B35: ΔV supply droop (V) | C35: 0 | D35: V
B36: Coss scale factor (auto-selected by device type; override if needed) | C36: =IFERROR(VLOOKUP(B9,'MOSFET Reference Table'!$A:$O,15,0),0.35) -> 0.4 | D36: — | F36: ⚠ Coss is bias-dependent. Recommended scale factors by device type: Si planar (BS170, 2N7000): 0.40 | Si vertical DMOS (IRF510, IRF540, IRFZ44N): 0.35 | LDMOS (RD16HVF1, MRF101AN, BLF574): 0.85 (use Coss,er from datasheet if available). For best accuracy, measure Coss at Vds ≈ 0.5×Vcc with a VNA. ⚠ Vcc-dependency note: Coss decreases significantly at higher Vds. For Vcc far from the nominal design point (e.g. <5 V or >15 V), verify scale factor against Coss vs Vds curve in the datasheet or use manufacturer energy-equivalent Coss (Coss,er) if provided. | G36: ZVS quality factor k_coss (edit I36 to override (replace its formula with your value)) Si-planar (BS170, 2N7000): 0.40–0.50 Si vertical DMOS (IRF510, IRF540, IRFZ44N): 0.35 RF MOSFET LDMOS (RD16HVF1, BLF574): 0.05–0.10 Unknown / conservative: 0.25 (default) Formula: p_coss = 0.5 × Coss_eff × V_pk² × f × k_coss | H36: =IFERROR(IF(VLOOKUP(B9,'MOSFET Reference Table'!$A:$P,16,0)="Si-planar",0.4,IF(VLOOKUP(B9,'MOSFET Reference Table'!$A:$P,16,0)="Si-DMOS",0.35,IF(VLOOKUP(B9,'MOSFET Reference Table'!$A:$P,16,0)="LDMOS",0.08,IF(VLOOKUP(B9,'MOSFET Reference Table'!$A:$P,16,0)="GaN",0.05,0.25)))),0.25) -> 0.4 | I36: =H36 -> 0.4 | J36: ⚠ To override k_coss: type your value directly into I36 (replacing =H36 formula). Example: 0.08 for LDMOS/GaN ZVS, 0.35 for Si-DMOS poor-ZVS, 0.40–0.50 for Si-planar poor-ZVS. Default formula =H36 auto-selects by device type from H36. J95 now uses I36.
B37: V_DSS Safety Factor (×V_pk_nominal). Typical: 2.0× (steady-state), 2.5× (HF bench), 3.0× (severe mistuning / VLF high-V) | C37: 3 | D37: — | F37: ℹ Mistuned V_pk can reach 5×Vcc; see I82 for worst-case check. Guidelines: 2.0× steady-state only | 3.0× HF bench | 4.0× severe mistuning/VLF high-V.
B39: INTERMEDIATE CALCULATIONS | F39: =IF(NOT(ISNUMBER(C42)),"—",IF(0.576801*(1.0000086-0.414395/C19-0.577501/C19^2+0.205967/C19^3)*(C16-C35-C20)^2<4*(C22+C30+1.365*IFERROR(VLOOKUP(B9,'MOSFET Reference Table'!$A:$E,5,0)*1,0)+0.2116*C31)*C17,"⚠ LOW EFFICIENCY: Device Rds(on) losses are high relative to R_opt — predicted η < ~80% at this design point. This is a design quality warning, not a hard limit. "&"Reduce Pout, increase Vcc, or select a lower Rds(on) device. Max Pout ≈ "&TEXT(0.576801*(1.0000086-0.414395/C19-0.577501/C19^2+0.205967/C19^3)*(C16-C35-C20)^2/(4*(C22+C30+1.365*IFERROR(VLOOKUP(B9,'MOSFET Reference Table'!$A:$E,5,0)*1,0)+0.2116*C31)),"0.000")&" W","✅ Operating point is feasible — iterate.")) -> ✅ Operating point is feasible — iterate.
B40: Parameter | C40: Value | D40: Unit | F40: Comment
B41: Angular Frequency ω = 2π · f | C41: =2*PI()*C18*1000000 -> 87964594 | D41: rad/s | F41: ω = angular frequency used in all component formulas below
B42: Optimum Load Resistance R (Sokal eq.6, QL-corrected polynomial) | C42: =IF(C19<=1.7879,"⚠ QL≤min (1.7879) — C2→∞, Class-E boundary",(C44^2/C17)*0.576801*(1.0000086-0.414395/C19-0.577501/C19^2+0.205967/C19^3)) -> 32.289223 | D42: Ω | F42: Sokal AACD 2001 eq.6a (3rd-order, ±0.01%): R = Veff²/P_out · f(QL), where f(QL) = 0.576801×(1.0000086 − 0.414395/QL − 0.577501/QL² + 0.205967/QL³). η does not appear in the R formula (Sokal formulation); it enters the design only through the efficiency model (C88/J95) and I_dc (C43). The C6 convergence check validates this formula directly.
B43: DC Supply Current I_dc = P_out / (Vcc · η) | C43: =C17/(C44*IF(ISNUMBER(C88),C88,C21)) -> 0.10618789 | D43: A | F43: Average DC supply current. Uses V_eff=(Vcc−ΔV−Vo) in denominator. MOSFET (Vo=0): I_dc = Pout/((Vcc−ΔV)×η) ← IMPROVED (Sokal Eq.3 uses Vcc alone; ΔV correction here gives more accurate I_dc when supply droop ΔV>0). BJT (Vo>0): I_dc = Pout/((Vcc−ΔV−Vo)×η) — KNOWN CONSERVATIVE APPROXIMATION: overestimates I_dc by Vo/(Vcc−ΔV−Vo)×100% vs Sokal eq.3 which uses Vcc alone. Example: Vo=0.5V, Vcc=5V → +11% overestimate. This is intentional (safe-side for I_pk and thermal calculations). R formula (C42) and I_dc both use Veff consistently. Press F9 until C88 stabilises.
B44: Effective Drive Voltage V_eff = Vcc − V_sat | C44: =C16-C35-C20 -> 5 | D44: V | F44: Usable voltage swing. Vo (C20) = transistor voltage-saturation offset; use 0 for MOSFET (ideal switch), 0.1–1 V for BJT at low freq. Supply-wiring droop ΔV.
B46: CLASS-E COMPONENT VALUES (Sokal / Raab equations)
...

Sheet LPF Direct 5-poles
B2: LPF DIRECT-COUPLED TO DRAIN (Z_source = R_opt)
B4: Correct 5-element Chebyshev LPF designed at R_opt (actual Class-E drain impedance) as source. Based on Sokal/Raab equations and Williams & Taylor "Electronic Filter Design Handbook".
B5: By Emiliano Gonzalez LU3VEA – lu3vea@gmail.com – License: GPL v3
B7: ⚠ WHY THE 50Ω LPF IS WRONG FOR DIRECT DRAIN CONNECTION — A Class-E drain presents R_opt (not 50Ω) as its load. A Chebyshev LPF designed for 50Ω source gives WRONG component values: the source-side shunt cap C2 must use R_opt in its formula C=g/(R_opt×ωc), not 50Ω. Using 50Ω makes C2 ≈2× too small, losing 10–20 dB of harmonic rejection at 2f. This sheet computes the correct asymmetric LPF with Z_source=R_opt and Z_load=50Ω. For large impedance ratios (n=Z_load/R_opt > 1.5) an L-network before a symmetric 50Ω LPF (main sheet) is also valid.
B9: LINKED PARAMETERS (from Class-E Calculator sheet)
B10: Parameter | C10: Value | D10: Unit | F10: Comment
B11: Operating Frequency f | C11: ='Class-E Calculator'!C18 -> 14 | D11: MHz | F11: Fundamental — imported from main sheet C18.
B12: Optimum Load Resistance R_opt (Sokal eq.6 — actual drain load) | C12: ='Class-E Calculator'!C42 -> 32.289223 | D12: Ω | F12: R_opt is the real Class-E drain load impedance. This is the CORRECT LPF source impedance when the LPF is directly connected to the drain (no L-network). Typical: 5–50 Ω for HF QRP.
B13: Load Impedance Z_load (antenna / output) | C13: ='Class-E Calculator'!C25 -> 50 | D13: Ω | F13: Typically 50 Ω antenna. Change in main sheet C25.
B14: Supply Voltage Vcc | C14: ='Class-E Calculator'!C16 -> 5 | D14: V | F14: Used for V_pk and capacitor voltage-rating check.
B15: Output Power P_out | C15: ='Class-E Calculator'!C17 -> 0.4 | D15: W | F15: Used for inductor RMS current rating.
B17: INTERMEDIATE CALCULATIONS | F17: =IF('Class-E Calculator'!C25/'Class-E Calculator'!C42<1.5,"✅ Impedance ratio n<1.5 — direct asymmetric LPF is valid.",IF('Class-E Calculator'!C25/'Class-E Calculator'!C42<=3,"⚠ n="&TEXT('Class-E Calculator'!C25/'Class-E Calculator'!C42,"0.0")&" — Valid range, verify with LTspice.","🚨 n="&TEXT('Class-E Calculator'!C25/'Class-E Calculator'!C42,"0.0")&" — Use L-network + 50Ω LPF on main sheet instead.")) -> ⚠ n=02 — Valid range, verify with LTspice.
B18: Parameter | C18: Value | D18: Unit | F18: Comment
B19: LPF Cutoff Frequency fc = 1.40 × f | C19: =1.4*C11 -> 19.6 | D19: MHz | F19: fc=1.40×f keeps fundamental ≤0.1 dB insertion loss in passband. For narrowband or VHF use 1.2×f.
B20: LPF Angular Cutoff ωc = 2π·fc | C20: =2*PI()*C19*1000000 -> 1.2315043e+08 | D20: rad/s
B21: Impedance Ratio n = Z_load / R_opt (step-up) | C21: =IF(NOT(ISNUMBER(C12)),"⚠ R_opt invalid — fix QL on main sheet first",C13/C12) -> 1.5485043 | D21: — | F21: n>1 means step-up (R_opt < 50Ω, typical Class-E). n=1 → symmetric Chebyshev (Z0_eff = 50Ω). Shunt-C toward source uses R_opt; shunt-C toward load uses Z_load.
B22: Z0_eff = √(R_opt × Z_load) — geometric-mean reference impedance | C22: =IF(NOT(ISNUMBER(C12)),"⚠ R_opt invalid — fix QL on main sheet first",SQRT(C12*C13)) -> 40.180357 | D22: Ω | F22: Z0_eff = √(R_opt × Z_load). Used to scale all series-L values in the asymmetric ladder. Shunt caps are scaled independently: C_source-side with R_opt, C_load-side with Z_load. (Williams & Taylor, Electronic Filter Design Handbook, 4th ed., §11.2)
B23: Peak Drain Voltage V_pk ≈ 3.562 × Vcc (capacitor voltage-rating reference) | C23: =MAX(3.562*('Class-E Calculator'!C16-'Class-E Calculator'!C35-'Class-E Calculator'!C20)+'Class-E Calculator'!C20,3.562*('Class-E Calculator'!C16-'Class-E Calculator'!C20)+'Class-E Calculator'!C20) -> 17.81 | D23: V | F23: All LPF capacitors must be rated ≥ 2× V_pk. V_pk = MAX(3.562×(Vcc−ΔV−Vo)+Vo, 3.562×(Vcc−Vo)+Vo). [FIXED: Uses MAX to ensure capacitor voltage rating is never reduced by supply droop ΔV — the drain RF voltage swing is decoupled from DC supply droop by the RFC choke. Using the higher no-droop V_pk conservatively protects LPF capacitors.] Use NP0/C0G or silver-mica ≥100 V for HF QRP.
B24: RMS Output Current I_rms = √(P_out / Z_load) (inductor wire-gauge reference) | C24: =SQRT(C15/C13) -> 0.089442719 | D24: A | F24: Series inductors L1, L3, L5 carry this current. Min wire: 24 AWG ≤0.5A, 22 AWG ≤1A, 20 AWG ≤2A, 18 AWG ≤3A, 16 AWG ≤5A.
B26: LPF COMPONENT VALUES (5-element Chebyshev 0.1 dB, Z_source=R_opt → Z_load=50Ω)
B27: Parameter | C27: Value | D27: Unit | E27: Std 5% | F27: Comment
B28: LPF L1 (series, 5-el Chebyshev 0.1 dB: g1=1.1468) — drain-side series inductor | C28: =IF(NOT(ISNUMBER(C12)),"⚠ R_opt invalid — fix QL on main sheet first",IF(ISNUMBER(C21),IF(C21>3,"⚠ n>3: Use L-network + 50Ω LPF",1.1468*C22/C20),"⚠ n invalid")) -> 3.7416705e-07 | D28: H | F28: L1 = g1 × Z0_eff / ωc. First series inductor from drain node. Wind on T50-6 or T68-6; verify SRF > 10×f.
B29: LPF L1 [µH] | C29: =IF(ISNUMBER(C28),C28*1000000,C28) -> 0.37416705 | D29: µH | E29: =IFERROR(IF(ISNUMBER(C29),TEXT(10^INT(LOG10(ABS(C29)+1E-030))*CHOOSE(MATCH(C29/10^INT(LOG10(ABS(C29)+1E-030)),{0,1.048809,1.148913,1.249,1.396424,1.549193,1.697056,1.897367,2.097618,2.297825,2.545584,2.84605,3.146427,3.446738,3.746999,4.095119,4.495553,4.895917,5.344156,5.892368,6.493073,7.141428,7.842194,8.638287,9.539392},1),1,1.1,1.2,1.3,1.5,1.6,1.8,2,2.2,2.4,2.7,3,3.3,3.6,3.9,4.3,4.7,5.1,5.6,6.2,6.8,7.5,8.2,9.1,10),"0.##")&" "&D29,C29),"—") -> 0 µH
B30: LPF C2 (shunt to GND, 5-el Chebyshev 0.1 dB: g2=1.3712) — source-side shunt cap | C30: =IF(NOT(ISNUMBER(C12)),"⚠ R_opt invalid — fix QL on main sheet first",IF(C21>3,"⚠ n>3: Use L-network + 50Ω LPF",1.3712/(C12*C20))) -> 3.4483177e-10 | D30: F | F30: ⚠ C2 = g2/(R_opt×ωc) uses R_opt (not 50Ω) as source impedance. This is the shunt cap closest to the drain. Use NP0/C0G or silver-mica rated ≥2× V_pk.
B31: LPF C2 [pF] | C31: =IF(ISNUMBER(C30),C30*1000000000000,C30) -> 344.83177 | D31: pF | E31: =IFERROR(IF(ISNUMBER(C31),TEXT(10^INT(LOG10(ABS(C31)+1E-030))*CHOOSE(MATCH(C31/10^INT(LOG10(ABS(C31)+1E-030)),{0,1.048809,1.148913,1.249,1.396424,1.549193,1.697056,1.897367,2.097618,2.297825,2.545584,2.84605,3.146427,3.446738,3.746999,4.095119,4.495553,4.895917,5.344156,5.892368,6.493073,7.141428,7.842194,8.638287,9.539392},1),1,1.1,1.2,1.3,1.5,1.6,1.8,2,2.2,2.4,2.7,3,3.3,3.6,3.9,4.3,4.7,5.1,5.6,6.2,6.8,7.5,8.2,9.1,10),"0.##")&" "&D31,C31),"—") -> 360 pF
B32: LPF L3 (series, 5-el Chebyshev 0.1 dB: g3=1.9750) — centre series inductor | C32: =IF(NOT(ISNUMBER(C12)),"⚠ R_opt invalid — fix QL on main sheet first",IF(ISNUMBER(C21),IF(C21>3,"⚠ n>3: Use L-network + 50Ω LPF",1.975*C22/C20),"⚠ n invalid")) -> 6.4438431e-07 | D32: H | F32: L3 = g3 × Z0_eff / ωc. Largest series inductor; centre of the ladder. Wind on T50-6 or T68-6.
B33: LPF L3 [µH] | C33: =IF(ISNUMBER(C32),C32*1000000,C32) -> 0.64438431 | D33: µH | E33: =IFERROR(IF(ISNUMBER(C33),TEXT(10^INT(LOG10(ABS(C33)+1E-030))*CHOOSE(MATCH(C33/10^INT(LOG10(ABS(C33)+1E-030)),{0,1.048809,1.148913,1.249,1.396424,1.549193,1.697056,1.897367,2.097618,2.297825,2.545584,2.84605,3.146427,3.446738,3.746999,4.095119,4.495553,4.895917,5.344156,5.892368,6.493073,7.141428,7.842194,8.638287,9.539392},1),1,1.1,1.2,1.3,1.5,1.6,1.8,2,2.2,2.4,2.7,3,3.3,3.6,3.9,4.3,4.7,5.1,5.6,6.2,6.8,7.5,8.2,9.1,10),"0.##")&" "&D33,C33),"—") -> 01 µH
B34: LPF C4 (shunt to GND, 5-el Chebyshev 0.1 dB: g4=1.3712) — load-side shunt cap | C34: =IF(NOT(ISNUMBER(C12)),"⚠ R_opt invalid — fix QL on main sheet first",IF(NOT(ISNUMBER(C21)),"⚠ n invalid",IF(C21>3,"⚠ n>3: Use L-network + 50Ω LPF",1.3712/(C13*C20)))) -> 2.22687e-10 | D34: F | F34: C4 = g4/(Z_load×ωc) uses Z_load=50Ω. Note C4 ≠ C2 (asymmetric terminations). Place close to the antenna connector. NP0/C0G or silver-mica.
B35: LPF C4 [pF] | C35: =IF(ISNUMBER(C34),C34*1000000000000,C34) -> 222.687 | D35: pF | E35: =IFERROR(IF(ISNUMBER(C35),TEXT(10^INT(LOG10(ABS(C35)+1E-030))*CHOOSE(MATCH(C35/10^INT(LOG10(ABS(C35)+1E-030)),{0,1.048809,1.148913,1.249,1.396424,1.549193,1.697056,1.897367,2.097618,2.297825,2.545584,2.84605,3.146427,3.446738,3.746999,4.095119,4.495553,4.895917,5.344156,5.892368,6.493073,7.141428,7.842194,8.638287,9.539392},1),1,1.1,1.2,1.3,1.5,1.6,1.8,2,2.2,2.4,2.7,3,3.3,3.6,3.9,4.3,4.7,5.1,5.6,6.2,6.8,7.5,8.2,9.1,10),"0.##")&" "&D35,C35),"—") -> 220 pF
B36: LPF L5 (series, 5-el Chebyshev 0.1 dB: g5=1.1468) — antenna-side series inductor | C36: =IF(NOT(ISNUMBER(C12)),"⚠ R_opt invalid — fix QL on main sheet first",IF(ISNUMBER(C21),IF(C21>3,"⚠ n>3: Use L-network + 50Ω LPF",1.1468*C22/C20),"⚠ n invalid")) -> 3.7416705e-07 | D36: H | F36: L5 = g5 × Z0_eff / ωc. By symmetry L5=L1. Output series inductor toward antenna/load. L1=L5 always (symmetric g1=g5); only C2≠C4 due to unequal terminations.
B37: LPF L5 [µH] | C37: =IF(ISNUMBER(C36),C36*1000000,C36) -> 0.37416705 | D37: µH | E37: =IFERROR(IF(ISNUMBER(C37),TEXT(10^INT(LOG10(ABS(C37)+1E-030))*CHOOSE(MATCH(C37/10^INT(LOG10(ABS(C37)+1E-030)),{0,1.048809,1.148913,1.249,1.396424,1.549193,1.697056,1.897367,2.097618,2.297825,2.545584,2.84605,3.146427,3.446738,3.746999,4.095119,4.495553,4.895917,5.344156,5.892368,6.493073,7.141428,7.842194,8.638287,9.539392},1),1,1.1,1.2,1.3,1.5,1.6,1.8,2,2.2,2.4,2.7,3,3.3,3.6,3.9,4.3,4.7,5.1,5.6,6.2,6.8,7.5,8.2,9.1,10),"0.##")&" "&D37,C37),"—") -> 0 µH
B39: PERFORMANCE ESTIMATES
B40: Parameter | C40: Value | D40: Unit | F40: Comment
B41: Attenuation at 2nd harmonic (2f) ⚠ UPPER BOUND — symmetric formula used; actual can be 10–20 dB lower for n≠1 | C41: =-10*LOG10((1+(10^(0.1/10)-1)*(16*(2*C11/C19)^5-20*(2*C11/C19)^3+5*(2*C11/C19))^2)/(1+(10^(0.1/10)-1)*(16*(C11/C19)^5-20*(C11/C19)^3+5*(C11/C19))^2)) -> -16.587408 | D41: dBc | E41: =IF(C41<-50,"✅ UPPER BOUND ≥−50 dBc (see I41 for worst-case asymmetric estimate)",IF(C41<-43,"⚠ UPPER BOUND ≥−43 dBc (FCC only; see I41)","🚨 Fails FCC −43 dBc even as upper bound (see I41)")) -> 🚨 Fails FCC −43 dBc even as upper bound (see I41) | F41: =IF(C41<-50,"✅ "&TEXT(ABS(C41),"0.0")&" dBc at 2f — meets IARU −50 dBc and FCC §97.307 −43 dBc.","⚠ "&TEXT(ABS(C41),"0.0")&" dBc at 2f — insufficient for IARU −50 dBc. Increase filter order or lower fc.") -> ⚠ 17 dBc at 2f — insufficient for IARU −50 dBc. Increase filter order or lower fc. | H41: =IF(ABS(C21-1)>0.05,"⚠ ASYMMETRIC FILTER — n=Z_load/R_opt="&TEXT(C21,"0.00")&"×. The Chebyshev attenuation formula below assumes equal source/load impedances. For asymmetric terminations: (a) passband insertion-loss error ≈"&TEXT(ABS(10*LOG10((1+C21)^2/(4*C21))),"0.1")&" dB; (b) stopband attenuation at 2f/3f can be 10–20 dB LOWER than calculated when n>1.5. These C41/C42 values must be treated as UPPER BOUNDS only. Verify actual stopband depth with LTspice using R_opt as the source impedance.","✅ n≈1: near-symmetric — attenuation estimates reliable (error <1 dB).") -> ⚠ ASYMMETRIC FILTER — n=Z_load/R_opt=1,55×. The Chebyshev attenuation formula below assumes equal source/load impedances. For asymmetric terminations: (a) passband insertion-loss error ≈0 dB; (b) stopband attenuation at 2f/3f can be 10–20 dB LOWER than calculated when n>1.5. These C41/C42 values must be treated as UPPER BOUNDS only. Verify actual stopband depth with LTspice using R_opt as the source impedance. | I41: =IF(ABS(C21-1)>0.05, "Lower-bound estimate (worst-case asymmetric): "&TEXT(C41+20,"0.0")&" dBc at 2f (assumes up to 20 dB penalty for n="&TEXT(C21,"0.00")&"×). "&IF(C41+20<-50,"✅ Even worst-case meets IARU -50 dBc.",IF(C41+20<-43,"⚠ Worst-case meets FCC -43 dBc only — verify with LTspice.","🚨 Worst-case may fail FCC -43 dBc. Reduce fc or increase poles.")), "— (n≈1, penalty small)") -> Lower-bound estimate (worst-case asymmetric): 03 dBc at 2f (assumes up to 20 dB penalty for n=1,55×). 🚨 Worst-case may fail FCC -43 dBc. Reduce fc or increase poles.
B42: Attenuation at 3rd harmonic (3f) ⚠ UPPER BOUND — symmetric formula used; actual can be 10–20 dB lower for n≠1 | C42: =-10*LOG10((1+(10^(0.1/10)-1)*(16*(3*C11/C19)^5-20*(3*C11/C19)^3+5*(3*C11/C19))^2)/(1+(10^(0.1/10)-1)*(16*(C11/C19)^5-20*(C11/C19)^3+5*(C11/C19))^2)) -> -38.214328 | D42: dBc | E42: =IF(C42<-50,"✅ UPPER BOUND ≥−50 dBc at 3f (see I42)",IF(C42<-43,"⚠ UPPER BOUND ≥−43 dBc FCC only (see I42)","🚨 Fails FCC −43 dBc at 3f (upper bound; see I42)")) -> 🚨 Fails FCC −43 dBc at 3f (upper bound; see I42) | F42: =IF(C42<-50,"✅ "&TEXT(ABS(C42),"0.0")&" dBc at 3f — excellent harmonic rejection.","⚠ "&TEXT(ABS(C42),"0.0")&" dBc at 3f — add filter poles for IARU compliance.") -> ⚠ 38 dBc at 3f — add filter poles for IARU compliance. | H42: =H41 -> ⚠ ASYMMETRIC FILTER — n=Z_load/R_opt=1,55×. The Chebyshev attenuation formula below assumes equal source/load impedances. For asymmetric terminations: (a) passband insertion-loss error ≈0 dB; (b) stopband attenuation at 2f/3f can be 10–20 dB LOWER than calculated when n>1.5. These C41/C42 values must be treated as UPPER BOUNDS only. Verify actual stopband depth with LTspice using R_opt as the source impedance. | I42: =IF(ABS(C21-1)>0.05, "Lower-bound estimate (worst-case asymmetric): "&TEXT(C42+20,"0.0")&" dBc at 3f.", "—") -> Lower-bound estimate (worst-case asymmetric): -18 dBc at 3f.
B43: LPF Source Impedance Validity Check | F43: =IF('Class-E Calculator'!C65<0.1,"⚠ LPF SOURCE: No L-network on main sheet — LPF source IS R_opt. These attenuation values apply directly to this sheet's design.","ℹ L-network active on main sheet (Q="&TEXT('Class-E Calculator'!C65,"0.00")&"×). When using this LPF direct-coupled sheet, connect the LPF directly to the drain WITHOUT the main-sheet L-network. The two approaches are alternatives, not series.") -> ℹ L-network active on main sheet (Q=0,74×). When using this LPF direct-coupled sheet, connect the LPF directly to the drain WITHOUT the main-sheet L-network. The two approaches are alternatives, not series.

Sheet LPF Direct 7-pole
B2: LPF DIRECT-COUPLED TO DRAIN (7-pole, Z_source = R_opt)
B4: Correct 7-element Chebyshev LPF designed at R_opt (actual Class-E drain impedance) as source. Based on Sokal/Raab equations and Williams & Taylor "Electronic Filter Design Handbook". Seven poles provide ≥14 dB additional stopband rejection vs. the 5-pole design, targeting −65 dBc or better at 2f.
B5: By Emiliano Gonzalez LU3VEA – lu3vea@gmail.com – License: GPL v3
B7: ⚠ WHY THE 50Ω LPF IS WRONG FOR DIRECT DRAIN CONNECTION — A Class-E drain presents R_opt (not 50Ω) as its load. A Chebyshev LPF designed for 50Ω source gives WRONG component values: the source-side shunt cap C2 must use R_opt in its formula C=g/(R_opt×ωc), not 50Ω. Using 50Ω makes C2 ≈2× too small, losing 10–20 dB of harmonic rejection at 2f. This sheet computes the correct asymmetric 7-pole LPF with Z_source=R_opt and Z_load=50Ω. For large impedance ratios (n=Z_load/R_opt > 1.5) an L-network before a symmetric 50Ω LPF (main sheet) is also valid.
B9: LINKED PARAMETERS (from Class-E Calculator sheet)
B10: Parameter | C10: Value | D10: Unit | F10: Comment
B11: Operating Frequency f | C11: ='Class-E Calculator'!C18 -> 14 | D11: MHz | F11: Fundamental — imported from main sheet C18.
B12: Optimum Load Resistance R_opt (Sokal eq.6 — actual drain load) | C12: ='Class-E Calculator'!C42 -> 32.289223 | D12: Ω | F12: R_opt is the real Class-E drain load impedance. This is the CORRECT LPF source impedance when the LPF is directly connected to the drain (no L-network). Typical: 5–50 Ω for HF QRP.
B13: Load Impedance Z_load (antenna / output) | C13: ='Class-E Calculator'!C25 -> 50 | D13: Ω | F13: Typically 50 Ω antenna. Change in main sheet C25.
B14: Supply Voltage Vcc | C14: ='Class-E Calculator'!C16 -> 5 | D14: V | F14: Used for V_pk and capacitor voltage-rating check.
B15: Output Power P_out | C15: ='Class-E Calculator'!C17 -> 0.4 | D15: W | F15: Used for inductor RMS current rating.
B17: INTERMEDIATE CALCULATIONS | F17: =IF('Class-E Calculator'!C25/'Class-E Calculator'!C42<1.5,"✅ Impedance ratio n<1.5 — direct asymmetric LPF is valid.",IF('Class-E Calculator'!C25/'Class-E Calculator'!C42<=3,"⚠ n="&TEXT('Class-E Calculator'!C25/'Class-E Calculator'!C42,"0.0")&" — Valid range, verify with LTspice.","🚨 n="&TEXT('Class-E Calculator'!C25/'Class-E Calculator'!C42,"0.0")&" — Use L-network + 50Ω LPF on main sheet instead.")) -> ⚠ n=02 — Valid range, verify with LTspice.
B18: Parameter | C18: Value | D18: Unit | F18: Comment
B19: LPF Cutoff Frequency fc = 1.40 × f | C19: =1.4*C11 -> 19.6 | D19: MHz | F19: fc=1.40×f keeps fundamental ≤0.1 dB insertion loss in passband. For narrowband or VHF use 1.2×f.
B20: LPF Angular Cutoff ωc = 2π·fc | C20: =2*PI()*C19*1000000 -> 1.2315043e+08 | D20: rad/s
B21: Impedance Ratio n = Z_load / R_opt (step-up) | C21: =IF(NOT(ISNUMBER(C12)),"⚠ R_opt invalid — fix QL on main sheet first",C13/C12) -> 1.5485043 | D21: — | F21: n>1 means step-up (R_opt < 50Ω, typical Class-E). n=1 → symmetric Chebyshev (Z0_eff = 50Ω). Shunt-C toward source uses R_opt; centre shunt-C uses Z0_eff; shunt-C toward load uses Z_load.
B22: Z0_eff = √(R_opt × Z_load) — geometric-mean reference impedance | C22: =IF(NOT(ISNUMBER(C12)),"⚠ R_opt invalid — fix QL on main sheet first",SQRT(C12*C13)) -> 40.180357 | D22: Ω | F22: Z0_eff = √(R_opt × Z_load). Used to scale all series-L values. Shunt caps: C2 with R_opt, C4 with Z0_eff, C6 with Z_load. (Williams & Taylor, Electronic Filter Design Handbook, 4th ed., §11.2)
B23: Peak Drain Voltage V_pk ≈ 3.562 × Vcc (capacitor voltage-rating reference) | C23: =MAX(3.562*('Class-E Calculator'!C16-'Class-E Calculator'!C35-'Class-E Calculator'!C20)+'Class-E Calculator'!C20,3.562*('Class-E Calculator'!C16-'Class-E Calculator'!C20)+'Class-E Calculator'!C20) -> 17.81 | D23: V | F23: All LPF capacitors must be rated ≥ 2× V_pk. V_pk = MAX(3.562×(Vcc−ΔV−Vo)+Vo, 3.562×(Vcc−Vo)+Vo). [FIXED: Uses MAX to ensure capacitor voltage rating is never reduced by supply droop ΔV — the drain RF voltage swing is decoupled from DC supply droop by the RFC choke. Using the higher no-droop V_pk conservatively protects LPF capacitors.] Use NP0/C0G or silver-mica ≥100 V for HF QRP.
B24: RMS Output Current I_rms = √(P_out / Z_load) (inductor wire-gauge reference) | C24: =SQRT(C15/C13) -> 0.089442719 | D24: A | F24: Series inductors L1, L3, L5, L7 carry this current. Min wire: 24 AWG ≤0.5A, 22 AWG ≤1A, 20 AWG ≤2A, 18 AWG ≤3A, 16 AWG ≤5A.
B26: LPF COMPONENT VALUES (7-element Chebyshev 0.1 dB, Z_source=R_opt → Z_load=50Ω)
B27: Parameter | C27: Value | D27: Unit | E27: Std 5% | F27: Comment
B28: LPF L1 (series, 7-el Chebyshev 0.1 dB: g1=1.1812) — drain-side series inductor | C28: =IF(NOT(ISNUMBER(C12)),"⚠ R_opt invalid — fix QL on main sheet first",IF(ISNUMBER(C21),IF(C21>3,"⚠ n>3: Use L-network + 50Ω LPF",1.181203*C22/C20),"⚠ n invalid")) -> 3.8539174e-07 | D28: H | F28: L1 = g1 × Z0_eff / ωc. First series inductor from drain node. Wind on T50-6 or T68-6; verify SRF > 10×f.
B29: LPF L1 [µH] | C29: =IF(ISNUMBER(C28),C28*1000000,C28) -> 0.38539174 | D29: µH | E29: =IFERROR(IF(ISNUMBER(C29),TEXT(10^INT(LOG10(ABS(C29)+1E-030))*CHOOSE(MATCH(C29/10^INT(LOG10(ABS(C29)+1E-030)),{0,1.048809,1.148913,1.249,1.396424,1.549193,1.697056,1.897367,2.097618,2.297825,2.545584,2.84605,3.146427,3.446738,3.746999,4.095119,4.495553,4.895917,5.344156,5.892368,6.493073,7.141428,7.842194,8.638287,9.539392},1),1,1.1,1.2,1.3,1.5,1.6,1.8,2,2.2,2.4,2.7,3,3.3,3.6,3.9,4.3,4.7,5.1,5.6,6.2,6.8,7.5,8.2,9.1,10),"0.##")&" "&D29,C29),"—") -> 0 µH
B30: LPF C2 (shunt to GND, 7-el Chebyshev 0.1 dB: g2=1.4228) — source-side shunt cap | C30: =IF(NOT(ISNUMBER(C12)),"⚠ R_opt invalid — fix QL on main sheet first",IF(C21>3,"⚠ n>3: Use L-network + 50Ω LPF",1.422802/(C12*C20))) -> 3.5780874e-10 | D30: F | F30: ⚠ C2 = g2/(R_opt×ωc) uses R_opt (not 50Ω) as source impedance. This is the shunt cap closest to the drain. Use NP0/C0G or silver-mica rated ≥2× V_pk.
B31: LPF C2 [pF] | C31: =IF(ISNUMBER(C30),C30*1000000000000,C30) -> 357.80874 | D31: pF | E31: =IFERROR(IF(ISNUMBER(C31),TEXT(10^INT(LOG10(ABS(C31)+1E-030))*CHOOSE(MATCH(C31/10^INT(LOG10(ABS(C31)+1E-030)),{0,1.048809,1.148913,1.249,1.396424,1.549193,1.697056,1.897367,2.097618,2.297825,2.545584,2.84605,3.146427,3.446738,3.746999,4.095119,4.495553,4.895917,5.344156,5.892368,6.493073,7.141428,7.842194,8.638287,9.539392},1),1,1.1,1.2,1.3,1.5,1.6,1.8,2,2.2,2.4,2.7,3,3.3,3.6,3.9,4.3,4.7,5.1,5.6,6.2,6.8,7.5,8.2,9.1,10),"0.##")&" "&D31,C31),"—") -> 360 pF
B32: LPF L3 (series, 7-el Chebyshev 0.1 dB: g3=2.0967) — second series inductor | C32: =IF(NOT(ISNUMBER(C12)),"⚠ R_opt invalid — fix QL on main sheet first",IF(ISNUMBER(C21),IF(C21>3,"⚠ n>3: Use L-network + 50Ω LPF",2.096694*C22/C20),"⚠ n invalid")) -> 6.8408948e-07 | D32: H | F32: L3 = g3 × Z0_eff / ωc. Second series inductor in the ladder. Wind on T50-6 or T68-6.
B33: LPF L3 [µH] | C33: =IF(ISNUMBER(C32),C32*1000000,C32) -> 0.68408948 | D33: µH | E33: =IFERROR(IF(ISNUMBER(C33),TEXT(10^INT(LOG10(ABS(C33)+1E-030))*CHOOSE(MATCH(C33/10^INT(LOG10(ABS(C33)+1E-030)),{0,1.048809,1.148913,1.249,1.396424,1.549193,1.697056,1.897367,2.097618,2.297825,2.545584,2.84605,3.146427,3.446738,3.746999,4.095119,4.495553,4.895917,5.344156,5.892368,6.493073,7.141428,7.842194,8.638287,9.539392},1),1,1.1,1.2,1.3,1.5,1.6,1.8,2,2.2,2.4,2.7,3,3.3,3.6,3.9,4.3,4.7,5.1,5.6,6.2,6.8,7.5,8.2,9.1,10),"0.##")&" "&D33,C33),"—") -> 01 µH
B34: LPF C4 (shunt to GND, 7-el Chebyshev 0.1 dB: g4=1.5734) — centre shunt cap | C34: =IF(NOT(ISNUMBER(C12)),"⚠ R_opt invalid — fix QL on main sheet first",IF(NOT(ISNUMBER(C22)),"⚠ Z0_eff invalid",IF(C21>3,"⚠ n>3: Use L-network + 50Ω LPF",1.573396/(C22*C20)))) -> 3.1797158e-10 | D34: F | F34: C4 = g4/(Z0_eff×ωc) uses Z0_eff=√(R_opt×Z_load) as the reference impedance for the centre shunt capacitor. [CORRECTED: Previous version incorrectly used R_opt, over-sizing C4 by up to 24% for typical n=1.55 and degrading 2f stopband rejection by 3–7 dB. The correct asymmetric ladder formula (Williams & Taylor, Electronic Filter Design Handbook, §11.2) uses Z0_eff for the centre element, R_opt for the source-side cap (C2), and Z_load for the load-side cap (C6).] NP0/C0G or silver-mica; rated ≥2× V_pk. Verify final design with LTspice.
B35: LPF C4 [pF] | C35: =IF(ISNUMBER(C34),C34*1000000000000,C34) -> 317.97158 | D35: pF | E35: =IFERROR(IF(ISNUMBER(C35),TEXT(10^INT(LOG10(ABS(C35)+1E-030))*CHOOSE(MATCH(C35/10^INT(LOG10(ABS(C35)+1E-030)),{0,1.048809,1.148913,1.249,1.396424,1.549193,1.697056,1.897367,2.097618,2.297825,2.545584,2.84605,3.146427,3.446738,3.746999,4.095119,4.495553,4.895917,5.344156,5.892368,6.493073,7.141428,7.842194,8.638287,9.539392},1),1,1.1,1.2,1.3,1.5,1.6,1.8,2,2.2,2.4,2.7,3,3.3,3.6,3.9,4.3,4.7,5.1,5.6,6.2,6.8,7.5,8.2,9.1,10),"0.##")&" "&D35,C35),"—") -> 330 pF
B36: LPF L5 (series, 7-el Chebyshev 0.1 dB: g5=2.0967) — third series inductor | C36: =IF(NOT(ISNUMBER(C12)),"⚠ R_opt invalid — fix QL on main sheet first",IF(ISNUMBER(C21),IF(C21>3,"⚠ n>3: Use L-network + 50Ω LPF",2.096694*C22/C20),"⚠ n invalid")) -> 6.8408948e-07 | D36: H | F36: L5 = g5 × Z0_eff / ωc. Third series inductor. By symmetry L5=L3. Wind on T50-6 or T68-6.
B37: LPF L5 [µH] | C37: =IF(ISNUMBER(C36),C36*1000000,C36) -> 0.68408948 | D37: µH | E37: =IFERROR(IF(ISNUMBER(C37),TEXT(10^INT(LOG10(ABS(C37)+1E-030))*CHOOSE(MATCH(C37/10^INT(LOG10(ABS(C37)+1E-030)),{0,1.048809,1.148913,1.249,1.396424,1.549193,1.697056,1.897367,2.097618,2.297825,2.545584,2.84605,3.146427,3.446738,3.746999,4.095119,4.495553,4.895917,5.344156,5.892368,6.493073,7.141428,7.842194,8.638287,9.539392},1),1,1.1,1.2,1.3,1.5,1.6,1.8,2,2.2,2.4,2.7,3,3.3,3.6,3.9,4.3,4.7,5.1,5.6,6.2,6.8,7.5,8.2,9.1,10),"0.##")&" "&D37,C37),"—") -> 01 µH
B38: LPF C6 (shunt to GND, 7-el Chebyshev 0.1 dB: g6=1.4228) — load-side shunt cap | C38: =IF(NOT(ISNUMBER(C12)),"⚠ R_opt invalid — fix QL on main sheet first",IF(NOT(ISNUMBER(C21)),"⚠ n invalid",IF(C21>3,"⚠ n>3: Use L-network + 50Ω LPF",1.422802/(C13*C20)))) -> 2.3106732e-10 | D38: F | F38: C6 = g6/(Z_load×ωc) uses Z_load=50Ω. Note C6 ≠ C2 ≠ C4 (asymmetric terminations). Place close to the antenna connector. NP0/C0G or silver-mica.
B39: LPF C6 [pF] | C39: =IF(ISNUMBER(C38),C38*1000000000000,C38) -> 231.06732 | D39: pF | E39: =IFERROR(IF(ISNUMBER(C39),TEXT(10^INT(LOG10(ABS(C39)+1E-030))*CHOOSE(MATCH(C39/10^INT(LOG10(ABS(C39)+1E-030)),{0,1.048809,1.148913,1.249,1.396424,1.549193,1.697056,1.897367,2.097618,2.297825,2.545584,2.84605,3.146427,3.446738,3.746999,4.095119,4.495553,4.895917,5.344156,5.892368,6.493073,7.141428,7.842194,8.638287,9.539392},1),1,1.1,1.2,1.3,1.5,1.6,1.8,2,2.2,2.4,2.7,3,3.3,3.6,3.9,4.3,4.7,5.1,5.6,6.2,6.8,7.5,8.2,9.1,10),"0.##")&" "&D39,C39),"—") -> 240 pF
B40: LPF L7 (series, 7-el Chebyshev 0.1 dB: g7=1.1812) — antenna-side series inductor | C40: =IF(NOT(ISNUMBER(C12)),"⚠ R_opt invalid — fix QL on main sheet first",IF(ISNUMBER(C21),IF(C21>3,"⚠ n>3: Use L-network + 50Ω LPF",1.181203*C22/C20),"⚠ n invalid")) -> 3.8539174e-07 | D40: H | F40: L7 = g7 × Z0_eff / ωc. By symmetry L7=L1. Output series inductor toward antenna/load. L1=L7 always (symmetric g1=g7 for odd-order Chebyshev).
B41: LPF L7 [µH] | C41: =IF(ISNUMBER(C40),C40*1000000,C40) -> 0.38539174 | D41: µH | E41: =IFERROR(IF(ISNUMBER(C41),TEXT(10^INT(LOG10(ABS(C41)+1E-030))*CHOOSE(MATCH(C41/10^INT(LOG10(ABS(C41)+1E-030)),{0,1.048809,1.148913,1.249,1.396424,1.549193,1.697056,1.897367,2.097618,2.297825,2.545584,2.84605,3.146427,3.446738,3.746999,4.095119,4.495553,4.895917,5.344156,5.892368,6.493073,7.141428,7.842194,8.638287,9.539392},1),1,1.1,1.2,1.3,1.5,1.6,1.8,2,2.2,2.4,2.7,3,3.3,3.6,3.9,4.3,4.7,5.1,5.6,6.2,6.8,7.5,8.2,9.1,10),"0.##")&" "&D41,C41),"—") -> 0 µH
B43: PERFORMANCE ESTIMATES
B44: Parameter | C44: Value | D44: Unit | F44: Comment
B45: Attenuation at 2nd harmonic (2f) ⚠ UPPER BOUND — symmetric formula used; actual can be 10–20 dB lower for n≠1 | C45: =-10*LOG10((1+(10^(0.1/10)-1)*(64*(2*C11/C19)^7-112*(2*C11/C19)^5+56*(2*C11/C19)^3-7*(2*C11/C19))^2)/(1+(10^(0.1/10)-1)*(64*(C11/C19)^7-112*(C11/C19)^5+56*(C11/C19)^3-7*(C11/C19))^2)) -> -32.064051 | D45: dBc | E45: =IF(C45<-50,"✅ UPPER BOUND ≥−50 dBc (see I45 for worst-case)",IF(C45<-43,"⚠ UPPER BOUND ≥−43 dBc (FCC only; see I45)","🚨 Fails FCC −43 dBc even as upper bound")) -> 🚨 Fails FCC −43 dBc even as upper bound | F45: =IF(C45<-50,"✅ "&TEXT(ABS(C45),"0.0")&" dBc at 2f — meets IARU −50 dBc limit. Excellent 7-pole performance.",IF(C45<-43,"⚠ "&TEXT(ABS(C45),"0.0")&" dBc — try fc=1.2×f for more stopband depth.","🚨 "&TEXT(ABS(C45),"0.0")&" dBc — reduce fc to 1.2×f.")) -> 🚨 32 dBc — reduce fc to 1.2×f. | H45: =IF(ABS(C21-1)>0.05,"⚠ ASYMMETRIC FILTER — n=Z_load/R_opt="&TEXT(C21,"0.00")&"×. The Chebyshev attenuation formula below assumes equal source/load impedances. For asymmetric terminations: (a) passband insertion-loss error ≈"&TEXT(ABS(10*LOG10((1+C21)^2/(4*C21))),"0.1")&" dB; (b) stopband attenuation at 2f/3f can be 10–20 dB LOWER than calculated when n>1.5. These C45/C46 values must be treated as UPPER BOUNDS only. Verify actual stopband depth with LTspice using R_opt as the source impedance.","✅ n≈1: near-symmetric — attenuation estimates reliable (error <1 dB).") -> ⚠ ASYMMETRIC FILTER — n=Z_load/R_opt=1,55×. The Chebyshev attenuation formula below assumes equal source/load impedances. For asymmetric terminations: (a) passband insertion-loss error ≈0 dB; (b) stopband attenuation at 2f/3f can be 10–20 dB LOWER than calculated when n>1.5. These C45/C46 values must be treated as UPPER BOUNDS only. Verify actual stopband depth with LTspice using R_opt as the source impedance. | I45: =IF(ABS(C21-1)>0.05, "Lower-bound estimate (worst-case asymmetric): "&TEXT(C45+20,"0.0")&" dBc at 2f (up to 20 dB penalty for n="&TEXT(C21,"0.00")&"×). "&IF(C45+20<-50,"✅ Even worst-case meets IARU -50 dBc.",IF(C45+20<-43,"⚠ Worst-case meets FCC -43 dBc only.","🚨 Worst-case may fail FCC -43 dBc.")), "— (n≈1, penalty small)") -> Lower-bound estimate (worst-case asymmetric): -12 dBc at 2f (up to 20 dB penalty for n=1,55×). 🚨 Worst-case may fail FCC -43 dBc.
B46: Attenuation at 3rd harmonic (3f) ⚠ UPPER BOUND — symmetric formula used; actual can be 10–20 dB lower for n≠1 | C46: =-10*LOG10((1+(10^(0.1/10)-1)*(64*(3*C11/C19)^7-112*(3*C11/C19)^5+56*(3*C11/C19)^3-7*(3*C11/C19))^2)/(1+(10^(0.1/10)-1)*(64*(C11/C19)^7-112*(C11/C19)^5+56*(C11/C19)^3-7*(C11/C19))^2)) -> -62.47285 | D46: dBc | E46: =IF(C46<-50,"✅ UPPER BOUND ≥−50 dBc at 3f (see I46)",IF(C46<-43,"⚠ UPPER BOUND ≥−43 dBc FCC only (see I46)","🚨 Fails FCC −43 dBc at 3f (upper bound; see I46)")) -> ✅ UPPER BOUND ≥−50 dBc at 3f (see I46) | F46: =IF(C46<-50,"✅ "&TEXT(ABS(C46),"0.0")&" dBc at 3f — meets IARU −50 dBc limit.",IF(C46<-43,"⚠ "&TEXT(ABS(C46),"0.0")&" dBc at 3f — FCC limit only.","🚨 "&TEXT(ABS(C46),"0.0")&" dBc — reduce fc or increase poles.")) -> ✅ 62 dBc at 3f — meets IARU −50 dBc limit. | H46: =H45 -> ⚠ ASYMMETRIC FILTER — n=Z_load/R_opt=1,55×. The Chebyshev attenuation formula below assumes equal source/load impedances. For asymmetric terminations: (a) passband insertion-loss error ≈0 dB; (b) stopband attenuation at 2f/3f can be 10–20 dB LOWER than calculated when n>1.5. These C45/C46 values must be treated as UPPER BOUNDS only. Verify actual stopband depth with LTspice using R_opt as the source impedance. | I46: =IF(ABS(C21-1)>0.05, "Lower-bound estimate (worst-case asymmetric): "&TEXT(C46+20,"0.0")&" dBc at 3f.", "—") -> Lower-bound estimate (worst-case asymmetric): -42 dBc at 3f.
B47: LPF Source Impedance Validity Check | F47: =IF('Class-E Calculator'!C65<0.1,"⚠ LPF SOURCE: No L-network present (C65<0.1). LPF source = R_opt. Use this sheet for direct drain connection.","ℹ L-network is active (C65≥0.1). For best accuracy use the 5-pole or 7-pole 50Ω LPF on the main sheet instead of this direct-drain sheet.") -> ℹ L-network is active (C65≥0.1). For best accuracy use the 5-pole or 7-pole 50Ω LPF on the main sheet instead of this direct-drain sheet.

Sheet Schematic 5-pole LPF
B2: CLASS-E RF AMPLIFIER · 5-POLE CHEBYSHEV LPF (Direct Drain)
B3: Correct 5-element Chebyshev LPF (0.1 dB ripple) · Z_source = R_opt · Z_load = 50 Ω
B4: By Emiliano Gonzalez LU3VEA – lu3vea@gmail.com – License: GPL v3
B6: POWER SUPPLY & RFC CHOKE
B8: +Vcc
B9: |
B10: [RFC] <── RF choke, isolates DC from RF
B11: |
B12: +───DRAIN───(NET)
B13: |
B14: [MOSFET]───SOURCE───GND
B15: |
... B37: COMPONENT VALUES (5% Standard — linked from calculated sheets)
B38: Ref | C38: Description | D38: Std 5% | E38: Unit | F38: Source sheet / note
B39: RFC | C39: RF Choke (≥50·R/ω) | D39: ='Class-E Calculator'!E55 -> 018 µH | E39: µH | F39: Class-E Calculator E55
B40: C1 | C40: Shunt cap drain-to-GND (total) | D40: ='Class-E Calculator'!E49 -> 075 pF | E40: pF | F40: Class-E Calculator E49 (incl. Coss_eff)
B41: L2 | C41: Series resonant inductor | D41: ='Class-E Calculator'!E51 -> 02 µH | E41: µH | F41: Class-E Calculator E51
B42: C2 | C42: Series resonant capacitor | D42: ='Class-E Calculator'!E53 -> 091 pF | E42: pF | F42: Class-E Calculator E53
B43: LPF-L1 | C43: LPF series inductor (drain side) | D43: ='LPF Direct 5-poles'!E29 -> 0 µH | E43: µH | F43: LPF Direct 5-poles E29
B44: LPF-C2 | C44: LPF shunt cap (source side, R_opt) | D44: ='LPF Direct 5-poles'!E31 -> 360 pF | E44: pF | F44: LPF Direct 5-poles E31
B45: LPF-L3 | C45: LPF centre series inductor | D45: ='LPF Direct 5-poles'!E33 -> 01 µH | E45: µH | F45: LPF Direct 5-poles E33
B46: LPF-C4 | C46: LPF shunt cap (load side, 50Ω) | D46: ='LPF Direct 5-poles'!E35 -> 220 pF | E46: pF | F46: LPF Direct 5-poles E35
B47: LPF-L5 | C47: LPF series inductor (antenna side) | D47: ='LPF Direct 5-poles'!E37 -> 0 µH | E47: µH | F47: LPF Direct 5-poles E37
B49: LINKED PARAMETERS (from Class-E Calculator)
B50: Operating Frequency f | C50: ='Class-E Calculator'!C18 -> 14 | D50: MHz
B51: R_opt (Class-E drain load) | C51: ='Class-E Calculator'!C42 -> 32.289223 | D51: Ω
B52: Supply Voltage Vcc | C52: ='Class-E Calculator'!C16 -> 5 | D52: V
B53: Output Power P_out | C53: ='Class-E Calculator'!C17 -> 0.4 | D53: W
B54: LPF Cutoff fc = 1.40 × f | C54: ='LPF Direct 5-poles'!C19 -> 19.6 | D54: MHz
B55: Atten. @ 2f (upper bound) | C55: ='LPF Direct 5-poles'!C41 -> -16.587408 | D55: dBc
B56: Atten. @ 3f (upper bound) | C56: ='LPF Direct 5-poles'!C42 -> -38.214328 | D56: dBc

Sheet Schematic 7-pole LPF
B2: CLASS-E RF AMPLIFIER · 7-POLE CHEBYSHEV LPF (Direct Drain)
B3: Correct 7-element Chebyshev LPF (0.1 dB ripple) · Z_source = R_opt · Z_load = 50 Ω
B4: By Emiliano Gonzalez LU3VEA – lu3vea@gmail.com – License: GPL v3
B6: POWER SUPPLY & RFC CHOKE
B8: +Vcc
B9: |
B10: [RFC] <── RF choke, isolates DC from RF
B11: |
B12: +───DRAIN───(NET)
B13: |
B14: [MOSFET]───SOURCE───GND
B15: |
... B39: COMPONENT VALUES (5% Standard — linked from calculated sheets)
B40: Ref | C40: Description | D40: Std 5% | E40: Unit | F40: Source sheet / note
B41: RFC | C41: RF Choke (≥50·R/ω) | D41: ='Class-E Calculator'!E55 -> 018 µH | E41: µH | F41: Class-E Calculator E55
B42: C1 | C42: Shunt cap drain-to-GND (total) | D42: ='Class-E Calculator'!E49 -> 075 pF | E42: pF | F42: Class-E Calculator E49 (incl. Coss_eff)
B43: L2 | C43: Series resonant inductor | D43: ='Class-E Calculator'!E51 -> 02 µH | E43: µH | F43: Class-E Calculator E51
B44: C2 | C44: Series resonant capacitor | D44: ='Class-E Calculator'!E53 -> 091 pF | E44: pF | F44: Class-E Calculator E53
B45: LPF-L1 | C45: LPF series inductor (drain side) | D45: ='LPF Direct 7-pole'!E29 -> 0 µH | E45: µH | F45: LPF Direct 7-pole E29
B46: LPF-C2 | C46: LPF shunt cap (source side, R_opt) | D46: ='LPF Direct 7-pole'!E31 -> 360 pF | E46: pF | F46: LPF Direct 7-pole E31
B47: LPF-L3 | C47: LPF 2nd series inductor | D47: ='LPF Direct 7-pole'!E33 -> 01 µH | E47: µH | F47: LPF Direct 7-pole E33
B48: LPF-C4 | C48: LPF centre shunt cap (Z0_eff) | D48: ='LPF Direct 7-pole'!E35 -> 330 pF | E48: pF | F48: LPF Direct 7-pole E35
B49: LPF-L5 | C49: LPF 3rd series inductor | D49: ='LPF Direct 7-pole'!E37 -> 01 µH | E49: µH | F49: LPF Direct 7-pole E37
B50: LPF-C6 | C50: LPF shunt cap (load side, 50Ω) | D50: ='LPF Direct 7-pole'!E39 -> 240 pF | E50: pF | F50: LPF Direct 7-pole E39
B51: LPF-L7 | C51: LPF series inductor (antenna side) | D51: ='LPF Direct 7-pole'!E41 -> 0 µH | E51: µH | F51: LPF Direct 7-pole E41
B53: LINKED PARAMETERS (from Class-E Calculator)
B54: Operating Frequency f | C54: ='Class-E Calculator'!C18 -> 14 | D54: MHz
B55: R_opt (Class-E drain load) | C55: ='Class-E Calculator'!C42 -> 32.289223 | D55: Ω
B56: Supply Voltage Vcc | C56: ='Class-E Calculator'!C16 -> 5 | D56: V
B57: Output Power P_out | C57: ='Class-E Calculator'!C17 -> 0.4 | D57: W
B58: LPF Cutoff fc = 1.40 × f | C58: ='LPF Direct 7-pole'!C19 -> 19.6 | D58: MHz
B59: Atten. @ 2f (upper bound) | C59: ='LPF Direct 7-pole'!C45 -> -32.064051 | D59: dBc
B60: Atten. @ 3f (upper bound) | C60: ='LPF Direct 7-pole'!C46 -> -62.47285 | D60: dBc

Sheet MOSFET Reference Table
A1: All parameters are typical values from manufacturer datasheets.
A2: =IF(COUNTA(A3:Q3)=17,"✅ Table header: 17 columns (A–Q) verified","⚠ Column count mismatch — VLOOKUP indices may be wrong") -> ✅ Table header: 17 columns (A–Q) verified
A3: Part No. | B3: Package | C3: V_DSS (V) | D3: I_D (A) | E3: R_ds(on) (Ω) | F3: C_iss (pF) | G3: C_oss (pF) | H3: P_D (W) | I3: f_T (MHz) | J3: Typical P_RF (W) | K3: RF Freq Range | L3: Applications & Notes | M3: T_j max (°C) | N3: V_gs(th) (V) | O3: Coss Scale (Empirical. Use Coss,er from datasheet when available) | P3: Device Type | Q3: Rds_T_exp
A4: BS170 | B4: TO-92 | C4: 60 | D4: 0.5 | E4: 5 | F4: 60 | G4: 12 | H4: 0.83 | I4: 300 | J4: ≤0.5 | K4: HF ≤14 MHz | L4: QRP Class-E staple; WSPR & CW beacons 160m–20m; small SOT-23 alt. also available | M4: 150 | N4: 0.8–2.4 | O4: 0.4 | P4: Si-planar | Q4: 2.5
A5: 2N7000 | B5: TO-92 | C5: 60 | D5: 0.2 | E5: 5.3 | F5: 50 | G5: 10 | H5: 0.4 | I5: 200 | J5: ≤0.3 | K5: HF ≤7 MHz | L5: Similar to BS170; popular in micro-power QRP Class-E | M5: 150 | N5: 0.8–3.0 | O5: 0.4 | P5: Si-planar | Q5: 2.5
A6: IRF510 | B6: TO-220 | C6: 100 | D6: 5.6 | E6: 0.54 | F6: 135 | G6: 100 | H6: 43 | I6: 50 | J6: 5–30 | K6: HF ≤18 MHz | L6: The classic ham MOSFET; cheap, available, used in thousands of QRP kits | M6: 150 | N6: 2.0–4.0 | O6: 0.35 | P6: Si-DMOS | Q6: 2.3
A7: IRF520 | B7: TO-220 | C7: 100 | D7: 9.2 | E7: 0.27 | F7: 180 | G7: 135 | H7: 50 | I7: 50 | J7: 10–40 | K7: HF ≤18 MHz | L7: Higher current IRF510; good 40–80m medium-power Class-E | M7: 150 | N7: 2.0–4.0 | O7: 0.35 | P7: Si-DMOS | Q7: 2.3
A8: IRF530 | B8: TO-220 | C8: 100 | D8: 14 | E8: 0.18 | F8: 400 | G8: 260 | H8: 88 | I8: 50 | J8: 20–80 | K8: HF ≤30 MHz | L8: Higher Coss but more power; push-pull Class-E to 80W, 80m–10m | M8: 150 | N8: 2.0–4.0 | O8: 0.35 | P8: Si-DMOS | Q8: 2.3
A9: IRF540 | B9: TO-220 | C9: 100 | D9: 28 | E9: 0.077 | F9: 800 | G9: 450 | H9: 150 | I9: 40 | J9: 50–150 | K9: HF ≤10 MHz | L9: High current; great 160m–40m; high Coss makes tuning more critical | M9: 150 | N9: 2.0–4.0 | O9: 0.35 | P9: Si-DMOS | Q9: 2.3
A10: IRFZ44N | B10: TO-220 | C10: 55 | D10: 49 | E10: 0.028 | F10: 3050 | G10: 930 | H10: 107 | I10: 30 | J10: 50–200 | K10: MF/LF ≤1 MHz | L10: Excellent VLF/MF/LF (136 kHz, 472 kHz) high-power Class-E; very low Rdson | M10: 150 | N10: 2.0–4.0 | O10: 0.35 | P10: Si-DMOS | Q10: 2.3
A11: FQP13N10 | B11: TO-220 | C11: 100 | D11: 13 | E11: 0.18 | F11: 1060 | G11: 380 | H11: 88 | I11: 60 | J11: 20–60 | K11: HF ≤30 MHz | L11: Popular in QRP kits; alternative to IRF530; good HF performance | M11: 150 | N11: 2.0–4.0 | O11: 0.35 | P11: Si-DMOS | Q11: 2.3
A12: RD16HVF1 | B12: LDMOS SM | C12: 50 | D12: 5.5 | E12: — | F12: 80 | G12: 15 | H12: 25 | I12: 520 | J12: 16 | K12: HF–VHF ≤175 MHz | L12: RF-optimised LDMOS; excellent 10m–40m Class-E; very low Coss advantage | M12: 200 | N12: 1.5–4.0 | O12: 0.85 | P12: LDMOS | Q12: 2.3
A13: RD06HVF1 | B13: LDMOS SM | C13: 50 | D13: 2 | E13: — | F13: 44 | G13: 9 | H13: 12.5 | I13: 520 | J13: 6 | K13: HF–VHF ≤175 MHz | L13: Lower power LDMOS; QRP Class-E to 50 MHz; clean spectrum | M13: 200 | N13: 1.5–4.0 | O13: 0.85 | P13: LDMOS | Q13: 2.3
A14: BLF574 | B14: SOT539 | C14: 65 | D14: 40 | E14: — | F14: 120 | G14: 25 | H14: 250 | I14: 600 | J14: 300 | K14: HF ≤30 MHz | L14: Professional LDMOS; very high efficiency; expensive but superb | M14: 200 | N14: 1.5–3.5 | O14: 0.85 | P14: LDMOS | Q14: 2.3
A15: IXFN55N50 | B15: TO-264 | C15: 500 | D15: 55 | E15: 0.065 | F15: 4900 | G15: 1200 | H15: 500 | I15: 0 | J15: 500+ | K15: VLF/LF/MF | L15: 500 V rated; handles >10 kV peak drain; ideal for VLF/LF/MF (136 kHz, 472 kHz) high-power Class-E. fT=0 in table (no RF fT spec) — RF capability warning suppressed for VLF/LF designs (<1 MHz). | M15: 150 | N15: 2.0–4.0 | O15: 0.35 | P15: Si-DMOS | Q15: 2.3
A16: 2SK2231 | B16: TO-220 | C16: 200 | D16: 7 | E16: 0.5 | F16: 450 | G16: 200 | H16: 40 | I16: 70 | J16: 10–20 | K16: HF ≤10 MHz | L16: Japanese RF MOSFET; excellent 160m–80m Class-E; good efficiency | M16: 150 | N16: 1.0–3.0 | O16: 0.35 | P16: Si-DMOS | Q16: 2.3
A17: MRF101AN | B17: NI-780 | C17: 65 | D17: 10 | E17: — | F17: 200 | G17: 18 | H17: 300 | I17: 1000 | J17: 100 | K17: HF ≤30 MHz | L17: NXP HF power LDMOS; designed for HF SSB/FM; excellent Class-E candidate. ⚠ I_D=10A in column D is the CONTINUOUS drain current rating; pulsed I_D(pulsed)=20A. Continuous I_pk (C84) must be ≤ 10A. | M17: 200 | N17: 1.5–3.5 | O17: 0.85 | P17: LDMOS | Q17: 2.3
A18: IRFP250 | B18: TO-247 | C18: 200 | D18: 30 | E18: 0.085 | F18: 1700 | G18: 700 | H18: 190 | I18: 35 | J18: 80–150 | K18: HF ≤10 MHz | L18: 200V rating gives headroom at high Vcc; popular in medium-power 160m–80m designs | M18: 150 | N18: 2.0–4.0 | O18: 0.35 | P18: Si-DMOS | Q18: 2.3
A19: VN66AF | B19: TO-202 | C19: 60 | D19: 2 | E19: 2.5 | F19: 50 | G19: 20 | H19: 12 | I19: 250 | J19: 2–5 | K19: HF ≤30 MHz | L19: ⚠ OBSOLETE (discontinued by Siliconix/Vishay ~2010). Old Siliconix RF MOSFET; used by Sokal in original Class-E papers up to 145 MHz. Replace with BS170, 2N7000, or BF862 for new designs. | M19: 150 | N19: 0.8–2.4 | O19: 0.4 | P19: Si-planar | Q19: 2.5
